Workbook

Sheet Dex
A1: Pokemon | B1: Name in file | C1: Sprite
A2: Bulbasaur | B2: =LOWER(A2) -> bulbasaur | C2: =(IMAGE("https://play.pokemonshowdown.com/sprites/gen5/"&B2&".png", 3))
A3: Ivysaur | B3: =LOWER(A3) -> ivysaur | C3: =(IMAGE("https://play.pokemonshowdown.com/sprites/gen5/"&B3&".png", 3))
A4: Venusaur | B4: =LOWER(A4) -> venusaur | C4: =(IMAGE("https://play.pokemonshowdown.com/sprites/gen5/"&B4&".png", 3))
A5: Venusaur-Gmax | B5: =LOWER(A5) -> venusaur-gmax | C5: =(IMAGE("https://play.pokemonshowdown.com/sprites/gen5/"&B5&".png", 3))
A6: Venusaur-Mega | B6: =LOWER(A6) -> venusaur-mega | C6: =(IMAGE("https://play.pokemonshowdown.com/sprites/gen5/"&B6&".png", 3))
A7: Charmander | B7: =LOWER(A7) -> charmander | C7: =(IMAGE("https://play.pokemonshowdown.com/sprites/gen5/"&B7&".png", 3))
A8: Charmeleon | B8: =LOWER(A8) -> charmeleon | C8: =(IMAGE("https://play.pokemonshowdown.com/sprites/gen5/"&B8&".png", 3))
A9: Charizard | B9: =LOWER(A9) -> charizard | C9: =(IMAGE("https://play.pokemonshowdown.com/sprites/gen5/"&B9&".png", 3))
A10: Charizard-Gmax | B10: =LOWER(A10) -> charizard-gmax | C10: =(IMAGE("https://play.pokemonshowdown.com/sprites/gen5/"&B10&".png", 3))
A11: Charizard-Mega-X | B11: charizard-megax | C11: =(IMAGE("https://play.pokemonshowdown.com/sprites/gen5/"&B11&".png", 3))
A12: Charizard-Mega-Y | B12: charizard-megay | C12: =(IMAGE("https://play.pokemonshowdown.com/sprites/gen5/"&B12&".png", 3))
A13: Squirtle | B13: =LOWER(A13) -> squirtle | C13: =(IMAGE("https://play.pokemonshowdown.com/sprites/gen5/"&B13&".png", 3))
A14: Wartortle | B14: =LOWER(A14) -> wartortle | C14: =(IMAGE("https://play.pokemonshowdown.com/sprites/gen5/"&B14&".png", 3))
A15: Blastoise | B15: =LOWER(A15) -> blastoise | C15: =(IMAGE("https://play.pokemonshowdown.com/sprites/gen5/"&B15&".png", 3))
A16: Blastoise-Gmax | B16: =LOWER(A16) -> blastoise-gmax | C16: =(IMAGE("https://play.pokemonshowdown.com/sprites/gen5/"&B16&".png", 3))
A17: Blastoise-Mega | B17: =LOWER(A17) -> blastoise-mega | C17: =(IMAGE("https://play.pokemonshowdown.com/sprites/gen5/"&B17&".png", 3))
A18: Caterpie | B18: =LOWER(A18) -> caterpie | C18: =(IMAGE("https://play.pokemonshowdown.com/sprites/gen5/"&B18&".png", 3))
A19: Metapod | B19: =LOWER(A19) -> metapod | C19: =(IMAGE("https://play.pokemonshowdown.com/sprites/gen5/"&B19&".png", 3))
A20: Butterfree | B20: =LOWER(A20) -> butterfree | C20: =(IMAGE("https://play.pokemonshowdown.com/sprites/gen5/"&B20&".png", 3))
A21: Butterfree-Gmax | B21: =LOWER(A21) -> butterfree-gmax | C21: =(IMAGE("https://play.pokemonshowdown.com/sprites/gen5/"&B21&".png", 3))
A22: Weedle | B22: =LOWER(A22) -> weedle | C22: =(IMAGE("https://play.pokemonshowdown.com/sprites/gen5/"&B22&".png", 3))
A23: Kakuna | B23: =LOWER(A23) -> kakuna | C23: =(IMAGE("https://play.pokemonshowdown.com/sprites/gen5/"&B23&".png", 3))
A24: Beedrill | B24: =LOWER(A24) -> beedrill | C24: =(IMAGE("https://play.pokemonshowdown.com/sprites/gen5/"&B24&".png", 3))
... A45: Sandslash-Alola | B45: =LOWER(A45) -> sandslash-alola | C45: =(IMAGE("https://play.pokemonshowdown.com/sprites/gen5/"&B45&".png", 3))
A46: Nidoran-F | B46: nidoranf | C46: =(IMAGE("https://play.pokemonshowdown.com/sprites/gen5/"&B46&".png", 3))
A47: Nidorina | B47: =LOWER(A47) -> nidorina | C47: =(IMAGE("https://play.pokemonshowdown.com/sprites/gen5/"&B47&".png", 3))
A48: Nidoqueen | B48: =LOWER(A48) -> nidoqueen | C48: =(IMAGE("https://play.pokemonshowdown.com/sprites/gen5/"&B48&".png", 3))
A49: Nidoran-M | B49: nidoranm | C49: =(IMAGE("https://play.pokemonshowdown.com/sprites/gen5/"&B49&".png", 3))
A50: Nidorino | B50: =LOWER(A50) -> nidorino | C50: =(IMAGE("https://play.pokemonshowdown.com/sprites/gen5/"&B50&".png", 3))
A51: Nidoking | B51: =LOWER(A51) -> nidoking | C51: =(IMAGE("https://play.pokemonshowdown.com/sprites/gen5/"&B51&".png", 3))
A52: Clefairy | B52: =LOWER(A52) -> clefairy | C52: =(IMAGE("https://play.pokemonshowdown.com/sprites/gen5/"&B52&".png", 3))
A53: Clefable | B53: =LOWER(A53) -> clefable | C53: =(IMAGE("https://play.pokemonshowdown.com/sprites/gen5/"&B53&".png", 3))
A54: Vulpix | B54: =LOWER(A54) -> vulpix | C54: =(IMAGE("https://play.pokemonshowdown.com/sprites/gen5/"&B54&".png", 3))
A55: Vulpix-Alola | B55: =LOWER(A55) -> vulpix-alola | C55: =(IMAGE("https://play.pokemonshowdown.com/sprites/gen5/"&B55&".png", 3))
A56: Ninetales | B56: =LOWER(A56) -> ninetales | C56: =(IMAGE("https://play.pokemonshowdown.com/sprites/gen5/"&B56&".png", 3))
A57: Ninetales-Alola | B57: =LOWER(A57) -> ninetales-alola | C57: =(IMAGE("https://play.pokemonshowdown.com/sprites/gen5/"&B57&".png", 3))
A58: Jigglypuff | B58: =LOWER(A58) -> jigglypuff | C58: =(IMAGE("https://play.pokemonshowdown.com/sprites/gen5/"&B58&".png", 3))
A59: Wigglytuff | B59: =LOWER(A59) -> wigglytuff | C59: =(IMAGE("https://play.pokemonshowdown.com/sprites/gen5/"&B59&".png", 3))
A60: Zubat | B60: =LOWER(A60) -> zubat | C60: =(IMAGE("https://play.pokemonshowdown.com/sprites/gen5/"&B60&".png", 3))
...

Sheet Brawly Split
B1: Route 102
A2: Name | B2: Youngster Calvin
A3: Pokémon | B3: {=iferror(VLOOKUP(INDIRECT(ADDRESS(ROW()+1,COLUMN(), 4)),Dex!$A$2:$C293,3,false),"")} | C3: {=iferror(VLOOKUP(INDIRECT(ADDRESS(ROW()+1,COLUMN(), 4)),Dex!$A$2:$C293,3,false),"")} | D3: {=iferror(VLOOKUP(INDIRECT(ADDRESS(ROW()+1,COLUMN(), 4)),Dex!$A$2:$C293,3,false),"")} | H3: {=iferror(VLOOKUP("TRAINER_PIC_YOUNGSTER",Sprites!$A$1:$B293,2,false),"")}
B4: Poochyena | C4: Lillipup | D4: Rookidee
A5: Level | B5: 5 | C5: 6 | D5: 6
A6: Held Item
A7: Ability | B7: Rattled | C7: Vital Spirit | D7: Keen Eye
A8: Nature | B8: Bashful | C8: Bashful | D8: Bashful
A9: Moves | B9: Bite | C9: Tackle | D9: Wing Attack
B10: Quick Attack | C10: Bite | D10: Sand Attack
B11: Sand Attack | C11: Sand Attack | D11: Swagger
A13: Name | B13: Bug Catcher Rick
A14: Pokémon | B14: {=iferror(VLOOKUP(INDIRECT(ADDRESS(ROW()+1,COLUMN(), 4)),Dex!$A$2:$C293,3,false),"")} | C14: {=iferror(VLOOKUP(INDIRECT(ADDRESS(ROW()+1,COLUMN(), 4)),Dex!$A$2:$C293,3,false),"")} | D14: {=iferror(VLOOKUP(INDIRECT(ADDRESS(ROW()+1,COLUMN(), 4)),Dex!$A$2:$C293,3,false),"")} | H14: {=iferror(VLOOKUP("TRAINER_PIC_BUG_CATCHER",Sprites!$A$1:$B293,2,false),"")}
B15: Grubbin | C15: Pineco | D15: Sizzlipede
A16: Level | B16: 6 | C16: 6 | D16: 7
A17: Held Item | B17: Oran Berry | C17: Oran Berry | D17: Oran Berry
A18: Ability | B18: Swarm | C18: Sturdy | D18: Flash Fire
A19: Nature | B19: Bashful | C19: Bashful | D19: Bashful
A20: Moves | B20: Bug Bite | C20: Pin Missile | D20: Bug Bite
B21: Spark | C21: Iron Defense | D21: Ember
B22: Vise Grip | D22: Wrap
A24: Name | B24: Youngster Allen
A25: Pokémon | B25: {=iferror(VLOOKUP(INDIRECT(ADDRESS(ROW()+1,COLUMN(), 4)),Dex!$A$2:$C293,3,false),"")} | C25: {=iferror(VLOOKUP(INDIRECT(ADDRESS(ROW()+1,COLUMN(), 4)),Dex!$A$2:$C293,3,false),"")} | D25: {=iferror(VLOOKUP(INDIRECT(ADDRESS(ROW()+1,COLUMN(), 4)),Dex!$A$2:$C293,3,false),"")} | H25: {=iferror(VLOOKUP("TRAINER_PIC_YOUNGSTER",Sprites!$A$1:$B293,2,false),"")}
B26: Skiddo | C26: Litleo | D26: Psyduck
A27: Level | B27: 7 | C27: 6 | D27: 7
A28: Held Item | B28: Lum Berry | C28: Oran Berry | D28: Oran Berry
A29: Ability | B29: Sap Sipper | C29: Unnerve | D29: Swift Swim
A30: Nature | B30: Bashful | C30: Bashful | D30: Bashful
A31: Moves | B31: Vine Whip | C31: Headbutt | D31: Bubble Beam
B32: Tackle | C32: Ember | D32: Psywave
B33: Synthesis | C33: Work Up
A35: Name | B35: Lass Tiana
A36: Pokémon | B36: {=iferror(VLOOKUP(INDIRECT(ADDRESS(ROW()+1,COLUMN(), 4)),Dex!$A$2:$C293,3,false),"")} | C36: {=iferror(VLOOKUP(INDIRECT(ADDRESS(ROW()+1,COLUMN(), 4)),Dex!$A$2:$C293,3,false),"")} | H36: {=iferror(VLOOKUP("TRAINER_PIC_LASS",Sprites!$A$1:$B293,2,false),"")}
B37: Swirlix | C37: Spinda
A38: Level | B38: 7 | C38: 8
A39: Held Item | B39: Berry Juice | C39: Berry Juice
A40: Ability | B40: Unburden | C40: Own Tempo
A41: Nature | B41: Bashful | C41: Bashful
A42: Moves | B42: Fairy Wind | C42: Fake Out
B43: Metronome | C43: Metronome
...

Sheet Sprites
A1: TRAINER_PIC_AQUA_ADMIN_F
A2: TRAINER_PIC_AQUA_ADMIN_M
A3: TRAINER_PIC_AQUA_GRUNT_F
A4: TRAINER_PIC_AQUA_GRUNT_M
A5: TRAINER_PIC_AQUA_LEADER_ARCHIE
A6: TRAINER_PIC_ARENA_TYCOON_GRETA
A7: TRAINER_PIC_AROMA_LADY
A8: TRAINER_PIC_BATTLE_GIRL
A9: TRAINER_PIC_BEAUTY
A10: TRAINER_PIC_BIRD_KEEPER
A11: TRAINER_PIC_BLACK_BELT
A12: TRAINER_PIC_BRENDAN
... A95: TRAINER_PIC_YOUNGSTER

Sheet Roxanne Split
B1: Petalburg Woods
A2: Name | B2: Bug Catcher Lyle
A3: Pokémon | B3: {=iferror(VLOOKUP(INDIRECT(ADDRESS(ROW()+1,COLUMN(), 4)),Dex!$A$2:$C213,3,false),"")} | C3: {=iferror(VLOOKUP(INDIRECT(ADDRESS(ROW()+1,COLUMN(), 4)),Dex!$A$2:$C213,3,false),"")} | D3: {=iferror(VLOOKUP(INDIRECT(ADDRESS(ROW()+1,COLUMN(), 4)),Dex!$A$2:$C213,3,false),"")} | H3: {=iferror(VLOOKUP("TRAINER_PIC_BUG_CATCHER",Sprites!$A$1:$B213,2,false),"")}
B4: Ariados | C4: Kricketune | D4: Ninjask
A5: Level | B5: 21 | C5: 21 | D5: 21
A6: Held Item | B6: Scope Lens | C6: Lum Berry | D6: White Herb
A7: Ability | B7: Sniper | C7: Technician | D7: Speed Boost
A8: Nature | B8: Jolly | C8: Jolly | D8: Naughty
A9: Moves | B9: Cross Poison | C9: Bug Bite | D9: Leech Life
B10: Pin Missile | C10: Fell Stinger | D10: Dual Wingbeat
B11: Night Slash | C11: Rock Smash | D11: Giga Drain
B12: Shadow Sneak | C12: Aerial Ace
A13: Name | B13: Bug Maniac James
A14: Pokémon | B14: {=iferror(VLOOKUP(INDIRECT(ADDRESS(ROW()+1,COLUMN(), 4)),Dex!$A$2:$C213,3,false),"")} | C14: {=iferror(VLOOKUP(INDIRECT(ADDRESS(ROW()+1,COLUMN(), 4)),Dex!$A$2:$C213,3,false),"")} | D14: {=iferror(VLOOKUP(INDIRECT(ADDRESS(ROW()+1,COLUMN(), 4)),Dex!$A$2:$C213,3,false),"")} | E14: {=iferror(VLOOKUP(INDIRECT(ADDRESS(ROW()+1,COLUMN(), 4)),Dex!$A$2:$C213,3,false),"")} | H14: {=iferror(VLOOKUP("TRAINER_PIC_BUG_MANIAC",Sprites!$A$1:$B213,2,false),"")}
B15: Larvesta | C15: Vibrava | D15: Shedinja | E15: Ribombee
A16: Level | B16: 21 | C16: 21 | D16: 22 | E16: 21
A17: Held Item | B17: Eviolite | C17: Yache Berry | D17: Bright Powder | E17: Wise Glasses
A18: Ability | B18: Flame Body | C18: Levitate | D18: Wonder Guard | E18: Shield Dust
A19: Nature | B19: Careful | C19: Jolly | D19: Quiet | E19: Timid
A20: Moves | B20: Skitter Smack | C20: Stomping Tantrum | D20: X-Scissor | E20: Signal Beam
B21: Flame Charge | C21: Breaking Swipe | D21: Hex | E21: Draining Kiss
B22: Roost | C22: Bug Bite | D22: Shadow Sneak | E22: Magical Leaf
B23: Will-O-Wisp | C23: Roost | D23: Will-O-Wisp | E23: Fake Tears
B24: Route 104
A25: Name | B25: Rich Boy Winston
A26: Pokémon | B26: {=iferror(VLOOKUP(INDIRECT(ADDRESS(ROW()+1,COLUMN(), 4)),Dex!$A$2:$C213,3,false),"")} | C26: {=iferror(VLOOKUP(INDIRECT(ADDRESS(ROW()+1,COLUMN(), 4)),Dex!$A$2:$C213,3,false),"")} | H26: {=iferror(VLOOKUP("TRAINER_PIC_RICH_BOY",Sprites!$A$1:$B213,2,false),"")}
B27: Furfrou | C27: Mightyena
A28: Level | B28: 21 | C28: 22
A29: Held Item | B29: Leftovers | C29: Leftovers
A30: Ability | B30: Fur Coat | C30: Intimidate
A31: Nature | B31: Impish | C31: Jolly
A32: Moves | B32: Headbutt | C32: Crunch
B33: Covet | C33: Ice Fang
B34: Rock Smash | C34: Fire Fang
C35: Covet
A36: Name | B36: Fisherman Ivan
A37: Pokémon | B37: {=iferror(VLOOKUP(INDIRECT(ADDRESS(ROW()+1,COLUMN(), 4)),Dex!$A$2:$C213,3,false),"")} | C37: {=iferror(VLOOKUP(INDIRECT(ADDRESS(ROW()+1,COLUMN(), 4)),Dex!$A$2:$C213,3,false),"")} | D37: {=iferror(VLOOKUP(INDIRECT(ADDRESS(ROW()+1,COLUMN(), 4)),Dex!$A$2:$C213,3,false),"")} | H37: {=iferror(VLOOKUP("TRAINER_PIC_FISHERMAN",Sprites!$A$1:$B213,2,false),"")}
B38: Qwilfish | C38: Seadra | D38: Sealeo
A39: Level | B39: 22 | C39: 21 | D39: 21
A40: Held Item | B40: Black Sludge | C40: Lum Berry | D40: Lum Berry
...

Sheet Wattson Split
B1: Rusturf Tunnel
A2: Name | B2: Hiker Mike
A3: Pokémon | B3: {=iferror(VLOOKUP(INDIRECT(ADDRESS(ROW()+1,COLUMN(), 4)),Dex!$A$2:$C237,3,false),"")} | C3: {=iferror(VLOOKUP(INDIRECT(ADDRESS(ROW()+1,COLUMN(), 4)),Dex!$A$2:$C237,3,false),"")} | D3: {=iferror(VLOOKUP(INDIRECT(ADDRESS(ROW()+1,COLUMN(), 4)),Dex!$A$2:$C237,3,false),"")} | E3: {=iferror(VLOOKUP(INDIRECT(ADDRESS(ROW()+1,COLUMN(), 4)),Dex!$A$2:$C237,3,false),"")} | H3: {=iferror(VLOOKUP("TRAINER_PIC_HIKER",Sprites!$A$1:$B237,2,false),"")}
B4: Sandaconda | C4: Probopass | D4: Stoutland | E4: Clefable
A5: Level | B5: 25 | C5: 26 | D5: 26 | E5: 25
A6: Held Item | B6: Lum Berry | C6: Leftovers | D6: Lum Berry | E6: Pixie Plate
A7: Ability | B7: Sand Spit | C7: Sand Force | D7: Sand Rush | E7: Magic Guard
A8: Nature | B8: Careful | C8: Modest | D8: Adamant | E8: Timid
A9: Moves | B9: Earthquake | C9: Power Gem | D9: Body Slam | E9: Draining Kiss
B10: Stone Edge | C10: Flash Cannon | D10: Play Rough | E10: Ice Beam
B11: Fire Fang | C11: Earth Power | D11: Submission | E11: Thunderbolt
B12: Glare | C12: Thunderbolt | D12: Howl | E12: Mystical Fire
B13: Route 117
A14: Name | B14: Breeder Lydia
A15: Pokémon | B15: {=iferror(VLOOKUP(INDIRECT(ADDRESS(ROW()+1,COLUMN(), 4)),Dex!$A$2:$C237,3,false),"")} | C15: {=iferror(VLOOKUP(INDIRECT(ADDRESS(ROW()+1,COLUMN(), 4)),Dex!$A$2:$C237,3,false),"")} | D15: {=iferror(VLOOKUP(INDIRECT(ADDRESS(ROW()+1,COLUMN(), 4)),Dex!$A$2:$C237,3,false),"")} | E15: {=iferror(VLOOKUP(INDIRECT(ADDRESS(ROW()+1,COLUMN(), 4)),Dex!$A$2:$C237,3,false),"")} | H15: {=iferror(VLOOKUP("TRAINER_PIC_POKEMON_BREEDER_F",Sprites!$A$1:$B237,2,false),"")}
B16: Gothitelle | C16: Hitmonchan | D16: Toxtricity | E16: Sableye
A17: Level | B17: 26 | C17: 26 | D17: 26 | E17: 27
A18: Held Item | B18: Leftovers | C18: Lum Berry | D18: Lum Berry | E18: Sitrus Berry
A19: Ability | B19: Shadow Tag | C19: Iron Fist | D19: Technician | E19: Prankster
A20: Nature | B20: Bold | C20: Jolly | D20: Rash | E20: Bold
A21: Moves | B21: Psychic | C21: Sky Uppercut | D21: Shock Wave | E21: Foul Play
B22: Draining Kiss | C22: Mach Punch | D22: Drain Punch | E22: Night Shade
B23: Calm Mind | C23: Ice Punch | D23: Payback | E23: Will-O-Wisp
B24: Rest | C24: Shadow Punch | D24: Shift Gear | E24: Recover
A25: Name | B25: Breeder Corgi
A26: Pokémon | B26: {=iferror(VLOOKUP(INDIRECT(ADDRESS(ROW()+1,COLUMN(), 4)),Dex!$A$2:$C237,3,false),"")} | C26: {=iferror(VLOOKUP(INDIRECT(ADDRESS(ROW()+1,COLUMN(), 4)),Dex!$A$2:$C237,3,false),"")} | D26: {=iferror(VLOOKUP(INDIRECT(ADDRESS(ROW()+1,COLUMN(), 4)),Dex!$A$2:$C237,3,false),"")} | E26: {=iferror(VLOOKUP(INDIRECT(ADDRESS(ROW()+1,COLUMN(), 4)),Dex!$A$2:$C237,3,false),"")} | F26: {=iferror(VLOOKUP(INDIRECT(ADDRESS(ROW()+1,COLUMN(), 4)),Dex!$A$2:$C237,3,false),"")} | H26: {=iferror(VLOOKUP("TRAINER_PIC_POKEMON_BREEDER_M",Sprites!$A$1:$B237,2,false),"")}
B27: Arcanine | C27: Furfrou | D27: Lucario | E27: Manectric | F27: Boltund
A28: Level | B28: 27 | C28: 28 | D28: 27 | E28: 27 | F28: 27
A29: Held Item | B29: Sitrus Berry | C29: Leftovers | D29: Lum Berry | E29: Lum Berry | F29: Focus Sash
A30: Ability | B30: Intimidate | C30: Fur Coat | D30: Steadfast | E30: Static | F30: Strong Jaw
A31: Nature | B31: Jolly | C31: Jolly | D31: Timid | E31: Naive | F31: Jolly
A32: Moves | B32: Flare Blitz | C32: Return | D32: Aura Sphere | E32: Thunderbolt | F32: Thunder Fang
B33: Wild Charge | C33: Iron Tail | D33: Flash Cannon | E33: Flamethrower | F33: Psychic Fangs
B34: Extreme Speed | C34: Play Rough | D34: Shadow Ball | E34: Crunch | F34: Crunch
B35: Will-O-Wisp | C35: Attract | D35: Magnet Rise | E35: Ice Fang | F35: Howl
A36: Name | B36: Psychic Brandi & Battle Girl Aisha [Double]
A37: Pokémon | B37: {=iferror(VLOOKUP(INDIRECT(ADDRESS(ROW()+1,COLUMN(), 4)),Dex!$A$2:$C237,3,false),"")} | C37: {=iferror(VLOOKUP(INDIRECT(ADDRESS(ROW()+1,COLUMN(), 4)),Dex!$A$2:$C237,3,false),"")} | E37: {=iferror(VLOOKUP(INDIRECT(ADDRESS(ROW()+1,COLUMN(), 4)),Dex!$A$2:$C237,3,false),"")} | F37: {=iferror(VLOOKUP(INDIRECT(ADDRESS(ROW()+1,COLUMN(), 4)),Dex!$A$2:$C237,3,false),"")} | H37: {=iferror(VLOOKUP("TRAINER_PIC_BATTLE_GIRL",Sprites!$A$1:$B237,2,false),"")}
B38: Orbeetle | C38: Hypno | E38: Toxicroak | F38: Hariyama
A39: Level | B39: 27 | C39: 27 | E39: 27 | F39: 27
A40: Held Item | B40: Lum Berry | C40: Sitrus Berry | E40: Payapa Berry | F40: Lum Berry
...

Sheet Norman Split
B1: Route 110
A2: Name | B2: Psychic Jaclyn
A3: Pokémon | B3: {=iferror(VLOOKUP(INDIRECT(ADDRESS(ROW()+1,COLUMN(), 4)),Dex!$A$2:$C289,3,false),"")} | C3: {=iferror(VLOOKUP(INDIRECT(ADDRESS(ROW()+1,COLUMN(), 4)),Dex!$A$2:$C289,3,false),"")} | D3: {=iferror(VLOOKUP(INDIRECT(ADDRESS(ROW()+1,COLUMN(), 4)),Dex!$A$2:$C289,3,false),"")} | E3: {=iferror(VLOOKUP(INDIRECT(ADDRESS(ROW()+1,COLUMN(), 4)),Dex!$A$2:$C289,3,false),"")} | H3: {=iferror(VLOOKUP("TRAINER_PIC_PSYCHIC_F",Sprites!$A$1:$B289,2,false),"")}
B4: Venomoth | C4: Xatu | D4: Grumpig | E4: Gallade
A5: Level | B5: 34 | C5: 33 | D5: 33 | E5: 33
A6: Held Item | B6: Lum Berry | C6: Sitrus Berry | D6: Salac Berry | E6: Lum Berry
A7: Ability | B7: Tinted Lens | C7: Magic Bounce | D7: Gluttony | E7: Inner Focus
A8: Nature | B8: Timid | C8: Hasty | D8: Modest | E8: Careful
A9: Moves | B9: Bug Buzz | C9: Extrasensory | D9: Extrasensory | E9: Drain Punch
B10: Sludge Bomb | C10: Drill Peck | D10: Focus Blast | E10: Psycho Cut
B11: Energy Ball | C11: Heat Wave | D11: Power Gem | E11: Shadow Sneak
B12: Psychic | C12: Light Screen | D12: Reflect | E12: Bulk Up
A13: Name | B13: Triathlete Abigail
A14: Pokémon | B14: {=iferror(VLOOKUP(INDIRECT(ADDRESS(ROW()+1,COLUMN(), 4)),Dex!$A$2:$C289,3,false),"")} | C14: {=iferror(VLOOKUP(INDIRECT(ADDRESS(ROW()+1,COLUMN(), 4)),Dex!$A$2:$C289,3,false),"")} | D14: {=iferror(VLOOKUP(INDIRECT(ADDRESS(ROW()+1,COLUMN(), 4)),Dex!$A$2:$C289,3,false),"")} | E14: {=iferror(VLOOKUP(INDIRECT(ADDRESS(ROW()+1,COLUMN(), 4)),Dex!$A$2:$C289,3,false),"")} | H14: {=iferror(VLOOKUP("TRAINER_PIC_CYCLING_TRIATHLETE_F",Sprites!$A$1:$B289,2,false),"")}
B15: Mienshao | C15: Ninjask | D15: Dugtrio | E15: Magneton
A16: Level | B16: 32 | C16: 33 | D16: 34 | E16: 34
A17: Held Item | B17: Wide Lens | C17: Choice Band | D17: Life Orb | E17: Eviolite
A18: Ability | B18: Reckless | C18: Infiltrator | D18: Arena Trap | E18: Magnet Pull
A19: Nature | B19: Jolly | C19: Adamant | D19: Jolly | E19: Timid
A20: Moves | B20: Jump Kick | C20: U-turn | D20: Earthquake | E20: Thunderbolt
B21: Stone Edge | D21: Stone Edge | E21: Flash Cannon
B22: Blaze Kick | D22: Night Slash | E22: Body Press
B23: Bounce | D23: Swagger | E23: Screech
A24: Name | B24: Triathlete Anthony
A25: Pokémon | B25: {=iferror(VLOOKUP(INDIRECT(ADDRESS(ROW()+1,COLUMN(), 4)),Dex!$A$2:$C289,3,false),"")} | C25: {=iferror(VLOOKUP(INDIRECT(ADDRESS(ROW()+1,COLUMN(), 4)),Dex!$A$2:$C289,3,false),"")} | D25: {=iferror(VLOOKUP(INDIRECT(ADDRESS(ROW()+1,COLUMN(), 4)),Dex!$A$2:$C289,3,false),"")} | H25: {=iferror(VLOOKUP("TRAINER_PIC_CYCLING_TRIATHLETE_M",Sprites!$A$1:$B289,2,false),"")}
B26: Luxray | C26: Sharpedo | D26: Braviary
A27: Level | B27: 34 | C27: 34 | D27: 34
A28: Held Item | B28: Lum Berry | C28: Expert Belt | D28: Sitrus Berry
A29: Ability | B29: Intimidate | C29: Speed Boost | D29: Defiant
A30: Nature | B30: Adamant | C30: Rash | D30: Adamant
A31: Moves | B31: Zing Zap | C31: Hydro Pump | D31: Return
B32: Play Rough | C32: Dark Pulse | D32: Dual Wingbeat
B33: Crunch | C33: Ice Beam | D33: Close Combat
B34: Agility | C34: Psychic Fangs | D34: Agility
A35: Name | B35: Triathlete Alyssa
A36: Pokémon | B36: {=iferror(VLOOKUP(INDIRECT(ADDRESS(ROW()+1,COLUMN(), 4)),Dex!$A$2:$C289,3,false),"")} | C36: {=iferror(VLOOKUP(INDIRECT(ADDRESS(ROW()+1,COLUMN(), 4)),Dex!$A$2:$C289,3,false),"")} | H36: {=iferror(VLOOKUP("TRAINER_PIC_CYCLING_TRIATHLETE_F",Sprites!$A$1:$B289,2,false),"")}
B37: Absol | C37: Meowstic-F
A38: Level | B38: 36 | C38: 37
A39: Held Item | B39: Focus Sash | C39: Wise Glasses
A40: Ability | B40: Super Luck | C40: Competitive
...

Sheet Flannery Split
B1: Winstrate House
A2: Name | B2: Winstrate Victor
A3: Pokémon | B3: {=iferror(VLOOKUP(INDIRECT(ADDRESS(ROW()+1,COLUMN(), 4)),Dex!$A$2:$C725,3,false),"")} | C3: {=iferror(VLOOKUP(INDIRECT(ADDRESS(ROW()+1,COLUMN(), 4)),Dex!$A$2:$C725,3,false),"")} | H3: {=iferror(VLOOKUP("TRAINER_PIC_POKEFAN_M",Sprites!$A$1:$B725,2,false),"")}
B4: Toucannon | C4: Emolga
A5: Level | B5: 43 | C5: 43
A6: Held Item | B6: Lum Berry | C6: Lum Berry
A7: Ability | B7: Skill Link | C7: Motor Drive
A8: Nature | B8: Hasty | C8: Hasty
A9: Moves | B9: Boomburst | C9: Thunderbolt
B10: Drill Peck | C10: Dual Wingbeat
B11: Bullet Seed | C11: Iron Tail
B12: Supersonic | C12: Roost
A13: Name | B13: Winstrate Victoria
A14: Pokémon | B14: {=iferror(VLOOKUP(INDIRECT(ADDRESS(ROW()+1,COLUMN(), 4)),Dex!$A$2:$C725,3,false),"")} | C14: {=iferror(VLOOKUP(INDIRECT(ADDRESS(ROW()+1,COLUMN(), 4)),Dex!$A$2:$C725,3,false),"")} | D14: {=iferror(VLOOKUP(INDIRECT(ADDRESS(ROW()+1,COLUMN(), 4)),Dex!$A$2:$C725,3,false),"")} | H14: {=iferror(VLOOKUP("TRAINER_PIC_POKEFAN_F",Sprites!$A$1:$B725,2,false),"")}
B15: Abomasnow | C15: Centiskorch | D15: Seismitoad
A16: Level | B16: 43 | C16: 44 | D16: 43
A17: Held Item | B17: Lum Berry | C17: Leftovers | D17: Lum Berry
A18: Ability | B18: Soundproof | C18: White Smoke | D18: Water Absorb
A19: Nature | B19: Hasty | C19: Careful | D19: Timid
A20: Moves | B20: Wood Hammer | C20: Fire Lash | D20: Earth Power
B21: Ice Beam | C21: Skitter Smack | D21: Muddy Water
B22: Ice Shard | C22: Coil | D22: Venoshock
B23: Earthquake | C23: Protect | D23: Toxic
A24: Name | B24: Winstrate Vivi
A25: Pokémon | B25: {=iferror(VLOOKUP(INDIRECT(ADDRESS(ROW()+1,COLUMN(), 4)),Dex!$A$2:$C725,3,false),"")} | C25: {=iferror(VLOOKUP(INDIRECT(ADDRESS(ROW()+1,COLUMN(), 4)),Dex!$A$2:$C725,3,false),"")} | D25: {=iferror(VLOOKUP(INDIRECT(ADDRESS(ROW()+1,COLUMN(), 4)),Dex!$A$2:$C725,3,false),"")} | H25: {=iferror(VLOOKUP("TRAINER_PIC_LASS",Sprites!$A$1:$B725,2,false),"")}
B26: Ribombee | C26: Flygon | D26: Sudowoodo
A27: Level | B27: 44 | C27: 43 | D27: 43
A28: Held Item | B28: Focus Sash | C28: Lum Berry | D28: Lum Berry
A29: Ability | B29: Shield Dust | C29: Levitate | D29: Rock Head
A30: Nature | B30: Timid | C30: Hasty | D30: Adamant
A31: Moves | B31: Dazzling Gleam | C31: Dragon Claw | D31: Head Smash
B32: Signal Beam | C32: Scorching Sands | D32: Double-Edge
B33: Energy Ball | C33: Flamethrower | D33: Wood Hammer
B34: Stun Spore | C34: Roost | D34: Submission
A35: Name | B35: Winstrate Vicky
A36: Pokémon | B36: {=iferror(VLOOKUP(INDIRECT(ADDRESS(ROW()+1,COLUMN(), 4)),Dex!$A$2:$C725,3,false),"")} | C36: {=iferror(VLOOKUP(INDIRECT(ADDRESS(ROW()+1,COLUMN(), 4)),Dex!$A$2:$C725,3,false),"")} | H36: {=iferror(VLOOKUP("TRAINER_PIC_EXPERT_F",Sprites!$A$1:$B725,2,false),"")}
B37: Medicham-Mega | C37: Krookodile
A38: Level | B38: 44 | C38: 44
A39: Held Item | B39: Medichamite | C39: Lum Berry
A40: Ability | B40: Pure Power | C40: Moxie
...

Sheet Winona Split
B1: Seashore House
A2: Name | B2: Tuber Simon
A3: Pokémon | B3: {=iferror(VLOOKUP(INDIRECT(ADDRESS(ROW()+1,COLUMN(), 4)),Dex!$A$2:$C794,3,false),"")} | C3: {=iferror(VLOOKUP(INDIRECT(ADDRESS(ROW()+1,COLUMN(), 4)),Dex!$A$2:$C794,3,false),"")} | D3: {=iferror(VLOOKUP(INDIRECT(ADDRESS(ROW()+1,COLUMN(), 4)),Dex!$A$2:$C794,3,false),"")} | E3: {=iferror(VLOOKUP(INDIRECT(ADDRESS(ROW()+1,COLUMN(), 4)),Dex!$A$2:$C794,3,false),"")} | F3: {=iferror(VLOOKUP(INDIRECT(ADDRESS(ROW()+1,COLUMN(), 4)),Dex!$A$2:$C794,3,false),"")} | G3: {=iferror(VLOOKUP(INDIRECT(ADDRESS(ROW()+1,COLUMN(), 4)),Dex!$A$2:$C794,3,false),"")} | H3: {=iferror(VLOOKUP("TRAINER_PIC_TUBER_M",Sprites!$A$1:$B794,2,false),"")}
B4: Floatzel | C4: Azumarill | D4: Dedenne | E4: Zangoose | F4: Persian | G4: Ludicolo
A5: Level | B5: 58 | C5: 57 | D5: 58 | E5: 57 | F5: 58 | G5: 58
A6: Held Item | B6: Flame Orb | C6: Assault Vest | D6: Petaya Berry | E6: Toxic Orb | F6: Leftovers | G6: Lum Berry
A7: Ability | B7: Water Veil | C7: Huge Power | D7: Cheek Pouch | E7: Toxic Boost | F7: Unnerve | G7: Own Tempo
A8: Nature | B8: Hasty | C8: Jolly | D8: Timid | E8: Jolly | F8: Timid | G8: Jolly
A9: Moves | B9: Aqua Tail | C9: Play Rough | D9: Thunderbolt | E9: Last Resort | F9: Hyper Voice | G9: Waterfall
B10: Ice Beam | C10: Aqua Tail | D10: Dazzling Gleam | E10: Retaliate | F10: Hypnosis | G10: Seed Bomb
B11: Knock Off | C11: Aqua Jet | D11: Grass Knot | F11: Nasty Plot | G11: Earthquake
B12: Switcheroo | C12: Ice Punch | D12: Endure | F12: Substitute | G12: Swords Dance
A13: Name | B13: Beauty Johanna
A14: Pokémon | B14: {=iferror(VLOOKUP(INDIRECT(ADDRESS(ROW()+1,COLUMN(), 4)),Dex!$A$2:$C794,3,false),"")} | C14: {=iferror(VLOOKUP(INDIRECT(ADDRESS(ROW()+1,COLUMN(), 4)),Dex!$A$2:$C794,3,false),"")} | D14: {=iferror(VLOOKUP(INDIRECT(ADDRESS(ROW()+1,COLUMN(), 4)),Dex!$A$2:$C794,3,false),"")} | E14: {=iferror(VLOOKUP(INDIRECT(ADDRESS(ROW()+1,COLUMN(), 4)),Dex!$A$2:$C794,3,false),"")} | F14: {=iferror(VLOOKUP(INDIRECT(ADDRESS(ROW()+1,COLUMN(), 4)),Dex!$A$2:$C794,3,false),"")} | G14: {=iferror(VLOOKUP(INDIRECT(ADDRESS(ROW()+1,COLUMN(), 4)),Dex!$A$2:$C794,3,false),"")} | H14: {=iferror(VLOOKUP("TRAINER_PIC_BEAUTY",Sprites!$A$1:$B794,2,false),"")}
B15: Nidoqueen | C15: Lapras | D15: Milotic | E15: Primarina | F15: Bruxish | G15: Tsareena
A16: Level | B16: 58 | C16: 58 | D16: 58 | E16: 58 | F16: 58 | G16: 58
A17: Held Item | B17: Black Sludge | C17: Leftovers | D17: Leftovers | E17: Leftovers | F17: Water Gem | G17: Wide Lens
A18: Ability | B18: Sheer Force | C18: Shell Armor | D18: Marvel Scale | E18: Torrent | F18: Strong Jaw | G18: Queenly Majesty
A19: Nature | B19: Bold | C19: Bold | D19: Sassy | E19: Bold | F19: Jolly | G19: Jolly
A20: Moves | B20: Sludge Wave | C20: Freeze-Dry | D20: Aqua Tail | E20: Scald | F20: Aqua Tail | G20: Power Whip
B21: Earth Power | C21: Thunderbolt | D21: Dragon Tail | E21: Draining Kiss | F21: Psychic Fangs | G21: High Jump Kick
B22: Lovely Kiss | C22: Protect | D22: Coil | E22: Calm Mind | F22: Crunch | G22: Knock Off
B23: Toxic Spikes | C23: Roar | D23: Rest | E23: Protect | F23: Screech | G23: Triple Axel
A24: Name | B24: Sailor Dwayne
A25: Pokémon | B25: {=iferror(VLOOKUP(INDIRECT(ADDRESS(ROW()+1,COLUMN(), 4)),Dex!$A$2:$C794,3,false),"")} | C25: {=iferror(VLOOKUP(INDIRECT(ADDRESS(ROW()+1,COLUMN(), 4)),Dex!$A$2:$C794,3,false),"")} | D25: {=iferror(VLOOKUP(INDIRECT(ADDRESS(ROW()+1,COLUMN(), 4)),Dex!$A$2:$C794,3,false),"")} | E25: {=iferror(VLOOKUP(INDIRECT(ADDRESS(ROW()+1,COLUMN(), 4)),Dex!$A$2:$C794,3,false),"")} | F25: {=iferror(VLOOKUP(INDIRECT(ADDRESS(ROW()+1,COLUMN(), 4)),Dex!$A$2:$C794,3,false),"")} | G25: {=iferror(VLOOKUP(INDIRECT(ADDRESS(ROW()+1,COLUMN(), 4)),Dex!$A$2:$C794,3,false),"")} | H25: {=iferror(VLOOKUP("TRAINER_PIC_SAILOR",Sprites!$A$1:$B794,2,false),"")}
B26: Clawitzer | C26: Gyarados | D26: Barbaracle | E26: Sharpedo | F26: Swalot | G26: Machamp
A27: Level | B27: 58 | C27: 58 | D27: 58 | E27: 58 | F27: 59 | G27: 59
A28: Held Item | B28: Lum Berry | C28: Wacan Berry | D28: White Herb | E28: Dark Gem | F28: Custap Berry | G28: Adrenaline Orb
A29: Ability | B29: Mega Launcher | C29: Intimidate | D29: Sniper | E29: Speed Boost | F29: Gluttony | G29: No Guard
A30: Nature | B30: Quiet | C30: Adamant | D30: Jolly | E30: Mild | F30: Careful | G30: Jolly
A31: Moves | B31: Water Pulse | C31: Waterfall | D31: Stone Edge | E31: Hydro Pump | F31: Gunk Shot | G31: Dynamic Punch
B32: Dragon Pulse | C32: Earthquake | D32: Razor Shell | E32: Dark Pulse | F32: Explosion | G32: Stone Edge
B33: Aura Sphere | C33: Lash Out | D33: Cross Chop | E33: Close Combat | F33: Earthquake | G33: Poison Jab
B34: Aqua Jet | C34: Thunder Wave | D34: Shell Smash | E34: Destiny Bond | F34: Curse | G34: Knock Off
B35: Route 105
A36: Name | B36: Swimmer♀ Imani [Optional]
A37: Pokémon | B37: {=iferror(VLOOKUP(INDIRECT(ADDRESS(ROW()+1,COLUMN(), 4)),Dex!$A$2:$C794,3,false),"")} | C37: {=iferror(VLOOKUP(INDIRECT(ADDRESS(ROW()+1,COLUMN(), 4)),Dex!$A$2:$C794,3,false),"")} | H37: {=iferror(VLOOKUP("TRAINER_PIC_SWIMMER_F",Sprites!$A$1:$B794,2,false),"")}
B38: Lumineon | C38: Bruxish
A39: Level | B39: 50 | C39: 50
A40: Held Item
...

Sheet Tate & Liza Split
B1: Route 120
A2: Name | B2: Bird Keeper Colin
A3: Pokémon | B3: {=iferror(VLOOKUP(INDIRECT(ADDRESS(ROW()+1,COLUMN(), 4)),Dex!$A$2:$C954,3,false),"")} | C3: {=iferror(VLOOKUP(INDIRECT(ADDRESS(ROW()+1,COLUMN(), 4)),Dex!$A$2:$C954,3,false),"")} | D3: {=iferror(VLOOKUP(INDIRECT(ADDRESS(ROW()+1,COLUMN(), 4)),Dex!$A$2:$C954,3,false),"")} | H3: {=iferror(VLOOKUP("TRAINER_PIC_BIRD_KEEPER",Sprites!$A$1:$B954,2,false),"")}
B4: Aerodactyl | C4: Charizard | D4: Empoleon
A5: Level | B5: 68 | C5: 69 | D5: 68
A6: Held Item | B6: Passho Berry | C6: Focus Sash | D6: Water Gem
A7: Ability | B7: Unnerve | C7: Blaze | D7: Defiant
A8: Nature | B8: Jolly | C8: Timid | D8: Jolly
A9: Moves | B9: Stone Edge | C9: Burn Up | D9: Iron Head
B10: Aqua Tail | C10: Hurricane | D10: Aqua Jet
B11: Substitute | C11: Weather Ball | D11: Drill Peck
B12: Swagger | C12: Counter | D12: Swords Dance
A13: Name | B13: Cool Trainer Gian
A14: Pokémon | B14: {=iferror(VLOOKUP(INDIRECT(ADDRESS(ROW()+1,COLUMN(), 4)),Dex!$A$2:$C954,3,false),"")} | C14: {=iferror(VLOOKUP(INDIRECT(ADDRESS(ROW()+1,COLUMN(), 4)),Dex!$A$2:$C954,3,false),"")} | D14: {=iferror(VLOOKUP(INDIRECT(ADDRESS(ROW()+1,COLUMN(), 4)),Dex!$A$2:$C954,3,false),"")} | E14: {=iferror(VLOOKUP(INDIRECT(ADDRESS(ROW()+1,COLUMN(), 4)),Dex!$A$2:$C954,3,false),"")} | F14: {=iferror(VLOOKUP(INDIRECT(ADDRESS(ROW()+1,COLUMN(), 4)),Dex!$A$2:$C954,3,false),"")} | H14: {=iferror(VLOOKUP("TRAINER_PIC_COOLTRAINER_M",Sprites!$A$1:$B954,2,false),"")}
B15: Drifblim | C15: Swampert | D15: Duraludon | E15: Alakazam | F15: Alcremie
A16: Level | B16: 69 | C16: 69 | D16: 68 | E16: 68 | F16: 70
A17: Held Item | B17: Colbur Berry | C17: Rindo Berry | D17: Leftovers | E17: Focus Sash | F17: Babiri Berry
A18: Ability | B18: Aftermath | C18: Torrent | D18: Heavy Metal | E18: Inner Focus | F18: Sweet Veil
A19: Nature | B19: Timid | C19: Adamant | D19: Relaxed | E19: Timid | F19: Bold
A20: Moves | B20: Air Slash | C20: Liquidation | D20: Draco Meteor | E20: Psychic | F20: Draining Kiss
B21: Explosion | C21: Flip Turn | D21: Dragon Tail | E21: Dazzling Gleam | F21: Stored Power
B22: Thunder | C22: Earthquake | D22: Heavy Slam | E22: Signal Beam | F22: Acid Armor
B23: Weather Ball | C23: Stealth Rock | D23: Body Press | E23: Counter | F23: Calm Mind
A24: Name | B24: Cool Trainer Jennifer & Battle Girl Callie [Double]
A25: Pokémon | B25: {=iferror(VLOOKUP(INDIRECT(ADDRESS(ROW()+1,COLUMN(), 4)),Dex!$A$2:$C954,3,false),"")} | C25: {=iferror(VLOOKUP(INDIRECT(ADDRESS(ROW()+1,COLUMN(), 4)),Dex!$A$2:$C954,3,false),"")} | D25: {=iferror(VLOOKUP(INDIRECT(ADDRESS(ROW()+1,COLUMN(), 4)),Dex!$A$2:$C954,3,false),"")} | F25: {=iferror(VLOOKUP(INDIRECT(ADDRESS(ROW()+1,COLUMN(), 4)),Dex!$A$2:$C954,3,false),"")} | G25: {=iferror(VLOOKUP(INDIRECT(ADDRESS(ROW()+1,COLUMN(), 4)),Dex!$A$2:$C954,3,false),"")} | H25: {=iferror(VLOOKUP("TRAINER_PIC_BATTLE_GIRL",Sprites!$A$1:$B954,2,false),"")}
B26: Metagross | C26: Ursaring | D26: Zebstrika | F26: Sawk | G26: Poliwrath
A27: Level | B27: 69 | C27: 69 | D27: 70 | F27: 70 | G27: 70
A28: Held Item | B28: Assault Vest | C28: Toxic Orb | D28: Life Orb | F28: Lum Berry | G28: Lum Berry
A29: Ability | B29: Clear Body | C29: Quick Feet | D29: Lightning Rod | F29: Sturdy | G29: Swift Swim
A30: Nature | B30: Jolly | C30: Jolly | D30: Jolly | F30: Jolly | G30: Lonely
A31: Moves | B31: Meteor Mash | C31: Facade | D31: Zing Zap | F31: Close Combat | G31: Close Combat
B32: Zen Headbutt | C32: Retaliate | D32: High Horsepower | F32: Throat Chop | G32: Hydro Pump
B33: Thunder Punch | C33: Gunk Shot | D33: Low Kick | F33: Coaching | G33: Coaching
B34: Icy Wind | C34: High Horsepower | D34: Magnet Rise | F34: Protect | G34: Hypnosis
A35: Name | B35: Parasol Lady Angelica
A36: Pokémon | B36: {=iferror(VLOOKUP(INDIRECT(ADDRESS(ROW()+1,COLUMN(), 4)),Dex!$A$2:$C954,3,false),"")} | C36: {=iferror(VLOOKUP(INDIRECT(ADDRESS(ROW()+1,COLUMN(), 4)),Dex!$A$2:$C954,3,false),"")} | D36: {=iferror(VLOOKUP(INDIRECT(ADDRESS(ROW()+1,COLUMN(), 4)),Dex!$A$2:$C954,3,false),"")} | E36: {=iferror(VLOOKUP(INDIRECT(ADDRESS(ROW()+1,COLUMN(), 4)),Dex!$A$2:$C954,3,false),"")} | H36: {=iferror(VLOOKUP("TRAINER_PIC_PARASOL_LADY",Sprites!$A$1:$B954,2,false),"")}
B37: Stunfisk | C37: Chansey | D37: Mismagius | E37: Musharna
A38: Level | B38: 70 | C38: 71 | D38: 69 | E38: 69
A39: Held Item | B39: Lum Berry | C39: Eviolite | D39: Ghost Gem | E39: Colbur Berry
A40: Ability | B40: Static | C40: Natural Cure | D40: Levitate | E40: Synchronize
...

Sheet Juan Split
B1: Mossdeep Space Center
A2: Name | B2: Team Magma Grunt Space Center #1
A3: Pokémon | B3: {=iferror(VLOOKUP(INDIRECT(ADDRESS(ROW()+1,COLUMN(), 4)),Dex!$A$2:$C893,3,false),"")} | C3: {=iferror(VLOOKUP(INDIRECT(ADDRESS(ROW()+1,COLUMN(), 4)),Dex!$A$2:$C893,3,false),"")} | D3: {=iferror(VLOOKUP(INDIRECT(ADDRESS(ROW()+1,COLUMN(), 4)),Dex!$A$2:$C893,3,false),"")} | E3: {=iferror(VLOOKUP(INDIRECT(ADDRESS(ROW()+1,COLUMN(), 4)),Dex!$A$2:$C893,3,false),"")} | F3: {=iferror(VLOOKUP(INDIRECT(ADDRESS(ROW()+1,COLUMN(), 4)),Dex!$A$2:$C893,3,false),"")} | H3: {=iferror(VLOOKUP("TRAINER_PIC_MAGMA_GRUNT_M",Sprites!$A$1:$B893,2,false),"")}
B4: Steelix | C4: Appletun | D4: Zebstrika | E4: Corviknight | F4: Simisear
A5: Level | B5: 84 | C5: 83 | D5: 84 | E5: 84 | F5: 85
A6: Held Item | B6: Bright Powder | C6: Lum Berry | D6: Focus Band | E6: Weakness Policy | F6: Focus Band
A7: Ability | B7: Sturdy | C7: Thick Fat | D7: Sap Sipper | E7: Unnerve | F7: Blaze
A8: Nature | B8: Brave | C8: Modest | D8: Naive | E8: Careful | F8: Timid
A9: Moves | B9: Earthquake | C9: Dragon Pulse | D9: Zing Zap | E9: Body Press | F9: Flamethrower
B10: Gyro Ball | C10: Apple Acid | D10: Overheat | E10: Power Trip | F10: Hidden Power Ice
B11: Explosion | C11: Leech Seed | D11: High Horsepower | E11: Iron Defense | F11: Grass Knot
B12: Stealth Rock | C12: Recover | D12: Low Kick | E12: Agility | F12: Nasty Plot
A13: Name | B13: Team Magma Grunt Space Center #2
A14: Pokémon | B14: {=iferror(VLOOKUP(INDIRECT(ADDRESS(ROW()+1,COLUMN(), 4)),Dex!$A$2:$C893,3,false),"")} | C14: {=iferror(VLOOKUP(INDIRECT(ADDRESS(ROW()+1,COLUMN(), 4)),Dex!$A$2:$C893,3,false),"")} | D14: {=iferror(VLOOKUP(INDIRECT(ADDRESS(ROW()+1,COLUMN(), 4)),Dex!$A$2:$C893,3,false),"")} | E14: {=iferror(VLOOKUP(INDIRECT(ADDRESS(ROW()+1,COLUMN(), 4)),Dex!$A$2:$C893,3,false),"")} | F14: {=iferror(VLOOKUP(INDIRECT(ADDRESS(ROW()+1,COLUMN(), 4)),Dex!$A$2:$C893,3,false),"")} | G14: {=iferror(VLOOKUP(INDIRECT(ADDRESS(ROW()+1,COLUMN(), 4)),Dex!$A$2:$C893,3,false),"")} | H14: {=iferror(VLOOKUP("TRAINER_PIC_MAGMA_GRUNT_M",Sprites!$A$1:$B893,2,false),"")}
B15: Scrafty | C15: Duraludon | D15: Exeggutor | E15: Aerodactyl | F15: Darmanitan | G15: Weavile
A16: Level | B16: 85 | C16: 84 | D16: 85 | E16: 84 | F16: 86 | G16: 86
A17: Held Item | B17: Assault Vest | C17: Iapapa Berry | D17: Quick Claw | E17: Scope Lens | F17: Life Orb | G17: Bright Powder
A18: Ability | B18: Intimidate | C18: Heavy Metal | D18: Chlorophyll | E18: Unnerve | F18: Sheer Force | G18: Inner Focus
A19: Nature | B19: Adamant | C19: Relaxed | D19: Quiet | E19: Jolly | F19: Jolly | G19: Jolly
A20: Moves | B20: Close Combat | C20: Draco Meteor | D20: Psychic | E20: Stone Edge | F20: Flare Blitz | G20: Night Slash
B21: Knock Off | C21: Heavy Slam | D21: Grass Knot | E21: Dual Wingbeat | F21: Earthquake | G21: Ice Shard
B22: Stone Edge | C22: Body Press | D22: Explosion | E22: Earthquake | F22: Rock Slide | G22: Low Kick
B23: Counter | C23: Stealth Rock | D23: Sleep Powder | E23: Dragon Dance | F23: Reversal | G23: Swords Dance
A24: Name | B24: Team Magma Grunt Space Center #3
A25: Pokémon | B25: {=iferror(VLOOKUP(INDIRECT(ADDRESS(ROW()+1,COLUMN(), 4)),Dex!$A$2:$C893,3,false),"")} | C25: {=iferror(VLOOKUP(INDIRECT(ADDRESS(ROW()+1,COLUMN(), 4)),Dex!$A$2:$C893,3,false),"")} | D25: {=iferror(VLOOKUP(INDIRECT(ADDRESS(ROW()+1,COLUMN(), 4)),Dex!$A$2:$C893,3,false),"")} | E25: {=iferror(VLOOKUP(INDIRECT(ADDRESS(ROW()+1,COLUMN(), 4)),Dex!$A$2:$C893,3,false),"")} | F25: {=iferror(VLOOKUP(INDIRECT(ADDRESS(ROW()+1,COLUMN(), 4)),Dex!$A$2:$C893,3,false),"")} | H25: {=iferror(VLOOKUP("TRAINER_PIC_MAGMA_GRUNT_F",Sprites!$A$1:$B893,2,false),"")}
B26: Diggersby | C26: Silvally-Grass | D26: Ribombee | E26: Arcanine | F26: Klinklang
A27: Level | B27: 85 | C27: 85 | D27: 85 | E27: 86 | F27: 86
A28: Held Item | B28: Quick Claw | C28: Grass Memory | D28: Focus Band | E28: Bright Powder | F28: Choice Band
A29: Ability | B29: Huge Power | C29: RKS System | D29: Shield Dust | E29: Intimidate | F29: Clear Body
A30: Nature | B30: Adamant | C30: Naive | D30: Modest | E30: Jolly | F30: Jolly
A31: Moves | B31: Double-Edge | C31: Multi-Attack | D31: Moonblast | E31: Flare Blitz | F31: Gear Grind
B32: Earthquake | C32: Flamethrower | D32: Bug Buzz | E32: Close Combat
B33: Fire Punch | C33: Ice Beam | D33: Hidden Power Fire | E33: Wild Charge
B34: Knock Off | C34: Imprison | D34: Quiver Dance | E34: Extreme Speed
A35: Name | B35: Magma Admin Courtney
A36: Pokémon | B36: {=iferror(VLOOKUP(INDIRECT(ADDRESS(ROW()+1,COLUMN(), 4)),Dex!$A$2:$C893,3,false),"")} | C36: {=iferror(VLOOKUP(INDIRECT(ADDRESS(ROW()+1,COLUMN(), 4)),Dex!$A$2:$C893,3,false),"")} | D36: {=iferror(VLOOKUP(INDIRECT(ADDRESS(ROW()+1,COLUMN(), 4)),Dex!$A$2:$C893,3,false),"")} | E36: {=iferror(VLOOKUP(INDIRECT(ADDRESS(ROW()+1,COLUMN(), 4)),Dex!$A$2:$C893,3,false),"")} | F36: {=iferror(VLOOKUP(INDIRECT(ADDRESS(ROW()+1,COLUMN(), 4)),Dex!$A$2:$C893,3,false),"")} | G36: {=iferror(VLOOKUP(INDIRECT(ADDRESS(ROW()+1,COLUMN(), 4)),Dex!$A$2:$C893,3,false),"")} | H36: {=iferror(VLOOKUP("TRAINER_PIC_MAGMA_GRUNT_F",Sprites!$A$1:$B893,2,false),"")}
B37: Shaymin | C37: Dugtrio | D37: Tyrantrum | E37: Xurkitree | F37: Buzzwole | G37: Charizard-Mega-X
A38: Level | B38: 87 | C38: 86 | D38: 86 | E38: 87 | F38: 87 | G38: 87
A39: Held Item | B39: Life Orb | C39: Ground Gem | D39: Focus Sash | E39: Leftovers | F39: Assault Vest | G39: Charizardite X
A40: Ability | B40: Natural Cure | C40: Arena Trap | D40: Rock Head | E40: Beast Boost | F40: Beast Boost | G40: Tough Claws
...

Sheet Victory Road Split
B1: Victory Road
A2: Name | B2: Trainer Wally
A3: Pokémon | B3: {=iferror(VLOOKUP(INDIRECT(ADDRESS(ROW()+1,COLUMN(), 4)),Dex!$A$2:$C367,3,false),"")} | C3: {=iferror(VLOOKUP(INDIRECT(ADDRESS(ROW()+1,COLUMN(), 4)),Dex!$A$2:$C367,3,false),"")} | D3: {=iferror(VLOOKUP(INDIRECT(ADDRESS(ROW()+1,COLUMN(), 4)),Dex!$A$2:$C367,3,false),"")} | E3: {=iferror(VLOOKUP(INDIRECT(ADDRESS(ROW()+1,COLUMN(), 4)),Dex!$A$2:$C367,3,false),"")} | F3: {=iferror(VLOOKUP(INDIRECT(ADDRESS(ROW()+1,COLUMN(), 4)),Dex!$A$2:$C367,3,false),"")} | G3: {=iferror(VLOOKUP(INDIRECT(ADDRESS(ROW()+1,COLUMN(), 4)),Dex!$A$2:$C367,3,false),"")} | H3: {=iferror(VLOOKUP("TRAINER_PIC_WALLY",Sprites!$A$1:$B367,2,false),"")}
B4: Vikavolt | C4: Roserade | D4: Azumarill | E4: Genesect | F4: Obstagoon | G4: Gardevoir-Mega
A5: Level | B5: 94 | C5: 94 | D5: 94 | E5: 95 | F5: 95 | G5: 95
A6: Held Item | B6: Focus Sash | C6: Life Orb | D6: Sitrus Berry | E6: Focus Sash | F6: Flame Orb | G6: Gardevoirite
A7: Ability | B7: Levitate | C7: Technician | D7: Huge Power | E7: Download | F7: Guts | G7: Pixilate
A8: Nature | B8: Modest | C8: Timid | D8: Jolly | E8: Hasty | F8: Jolly | G8: Timid
A9: Moves | B9: Thunderbolt | C9: Sludge Bomb | D9: Play Rough | E9: Bug Buzz | F9: Facade | G9: Psychic
B10: Bug Buzz | C10: Grass Knot | D10: Aqua Jet | E10: Flash Cannon | F10: Knock Off | G10: Hyper Voice
B11: Energy Ball | C11: Dazzling Gleam | D11: Knock Off | E11: Explosion | F11: Cross Chop | G11: Mystical Fire
B12: Sticky Web | C12: Hidden Power Fire | D12: Belly Drum | E12: Flamethrower | F12: Bulk Up | G12: Calm Mind
A13: Name | B13: Cool Trainer Hope & Cool Trainer Albert [Double]
A14: Pokémon | B14: {=iferror(VLOOKUP(INDIRECT(ADDRESS(ROW()+1,COLUMN(), 4)),Dex!$A$2:$C367,3,false),"")} | C14: {=iferror(VLOOKUP(INDIRECT(ADDRESS(ROW()+1,COLUMN(), 4)),Dex!$A$2:$C367,3,false),"")} | D14: {=iferror(VLOOKUP(INDIRECT(ADDRESS(ROW()+1,COLUMN(), 4)),Dex!$A$2:$C367,3,false),"")} | E14: {=iferror(VLOOKUP(INDIRECT(ADDRESS(ROW()+1,COLUMN(), 4)),Dex!$A$2:$C367,3,false),"")} | F14: {=iferror(VLOOKUP(INDIRECT(ADDRESS(ROW()+1,COLUMN(), 4)),Dex!$A$2:$C367,3,false),"")} | G14: {=iferror(VLOOKUP(INDIRECT(ADDRESS(ROW()+1,COLUMN(), 4)),Dex!$A$2:$C367,3,false),"")} | H14: {=iferror(VLOOKUP("TRAINER_PIC_COOLTRAINER_M",Sprites!$A$1:$B367,2,false),"")}
B15: Mamoswine | C15: Donphan | D15: Venusaur-Mega | E15: Aerodactyl-Mega | F15: Staraptor | G15: Hydreigon
A16: Level | B16: 94 | C16: 93 | D16: 95 | E16: 95 | F16: 93 | G16: 94
A17: Held Item | B17: Lum Berry | C17: Custap Berry | D17: Venusaurite | E17: Aerodactylite | F17: Flying Gem | G17: Fire Gem
A18: Ability | B18: Oblivious | C18: Sturdy | D18: Thick Fat | E18: Tough Claws | F18: Intimidate | G18: Levitate
A19: Nature | B19: Naive | C19: Adamant | D19: Naive | E19: Jolly | F19: Jolly | G19: Timid
A20: Moves | B20: Earthquake | C20: Earthquake | D20: Sludge Bomb | E20: Rock Slide | F20: Double-Edge | G20: Dragon Pulse
B21: Icicle Crash | C21: Stone Edge | D21: Giga Drain | E21: Dual Wingbeat | F21: Acrobatics | G21: Dark Pulse
B22: Freeze-Dry | C22: Knock Off | D22: Earthquake | E22: Fire Fang | F22: Close Combat | G22: Heat Wave
B23: Knock Off | C23: Endeavor | D23: Sleep Powder | E23: Tailwind | F23: Tailwind | G23: Tailwind
A24: Name | B24: Cool Trainer Katelynn
A25: Pokémon | B25: {=iferror(VLOOKUP(INDIRECT(ADDRESS(ROW()+1,COLUMN(), 4)),Dex!$A$2:$C367,3,false),"")} | C25: {=iferror(VLOOKUP(INDIRECT(ADDRESS(ROW()+1,COLUMN(), 4)),Dex!$A$2:$C367,3,false),"")} | D25: {=iferror(VLOOKUP(INDIRECT(ADDRESS(ROW()+1,COLUMN(), 4)),Dex!$A$2:$C367,3,false),"")} | E25: {=iferror(VLOOKUP(INDIRECT(ADDRESS(ROW()+1,COLUMN(), 4)),Dex!$A$2:$C367,3,false),"")} | F25: {=iferror(VLOOKUP(INDIRECT(ADDRESS(ROW()+1,COLUMN(), 4)),Dex!$A$2:$C367,3,false),"")} | G25: {=iferror(VLOOKUP(INDIRECT(ADDRESS(ROW()+1,COLUMN(), 4)),Dex!$A$2:$C367,3,false),"")} | H25: {=iferror(VLOOKUP("TRAINER_PIC_COOLTRAINER_F",Sprites!$A$1:$B367,2,false),"")}
B26: Walrein | C26: Yanmega | D26: Ludicolo | E26: Dugtrio | F26: Magnezone | G26: Pinsir-Mega
A27: Level | B27: 93 | C27: 93 | D27: 94 | E27: 94 | F27: 94 | G27: 95
A28: Held Item | B28: Lum Berry | C28: Leftovers | D28: Eject Pack | E28: Life Orb | F28: Air Balloon | G28: Pinsirite
A29: Ability | B29: Thick Fat | C29: Speed Boost | D29: Own Tempo | E29: Arena Trap | F29: Magnet Pull | G29: Aerilate
A30: Nature | B30: Bold | C30: Timid | D30: Timid | E30: Jolly | F30: Quiet | G30: Jolly
A31: Moves | B31: Ice Beam | C31: Bug Buzz | D31: Leaf Storm | E31: Earthquake | F31: Flash Cannon | G31: Earthquake
B32: Scald | C32: Air Slash | D32: Scald | E32: Stone Edge | F32: Discharge | G32: Frustration
B33: Whirlpool | C33: Hypnosis | D33: Knock Off | E33: Night Slash | F33: Explosion | G33: Quick Attack
B34: Super Fang | C34: Substitute | D34: Icy Wind | E34: Pursuit | F34: Hidden Power Fire | G34: Swords Dance
A35: Name | B35: Cool Trainer Quincy
A36: Pokémon | B36: {=iferror(VLOOKUP(INDIRECT(ADDRESS(ROW()+1,COLUMN(), 4)),Dex!$A$2:$C367,3,false),"")} | C36: {=iferror(VLOOKUP(INDIRECT(ADDRESS(ROW()+1,COLUMN(), 4)),Dex!$A$2:$C367,3,false),"")} | D36: {=iferror(VLOOKUP(INDIRECT(ADDRESS(ROW()+1,COLUMN(), 4)),Dex!$A$2:$C367,3,false),"")} | E36: {=iferror(VLOOKUP(INDIRECT(ADDRESS(ROW()+1,COLUMN(), 4)),Dex!$A$2:$C367,3,false),"")} | F36: {=iferror(VLOOKUP(INDIRECT(ADDRESS(ROW()+1,COLUMN(), 4)),Dex!$A$2:$C367,3,false),"")} | G36: {=iferror(VLOOKUP(INDIRECT(ADDRESS(ROW()+1,COLUMN(), 4)),Dex!$A$2:$C367,3,false),"")} | H36: {=iferror(VLOOKUP("TRAINER_PIC_COOLTRAINER_M",Sprites!$A$1:$B367,2,false),"")}
B37: Carbink | C37: Slowking | D37: Trevenant | E37: Muk | F37: Kommo-o | G37: Beedrill-Mega
A38: Level | B38: 94 | C38: 93 | D38: 93 | E38: 94 | F38: 94 | G38: 95
A39: Held Item | B39: Leftovers | C39: Assault Vest | D39: Sitrus Berry | E39: Black Sludge | F39: Dragon Gem | G39: Beedrillite
A40: Ability | B40: Sturdy | C40: Regenerator | D40: Harvest | E40: Poison Touch | F40: Overcoat | G40: Adaptability
...

Sheet Pokémon League
A1: Name | B1: Elite Four Sidney
A2: Pokémon | B2: {=iferror(VLOOKUP(INDIRECT(ADDRESS(ROW()+1,COLUMN(), 4)),Dex!$A$2:$C99,3,false),"")} | C2: {=iferror(VLOOKUP(INDIRECT(ADDRESS(ROW()+1,COLUMN(), 4)),Dex!$A$2:$C99,3,false),"")} | D2: {=iferror(VLOOKUP(INDIRECT(ADDRESS(ROW()+1,COLUMN(), 4)),Dex!$A$2:$C99,3,false),"")} | E2: {=iferror(VLOOKUP(INDIRECT(ADDRESS(ROW()+1,COLUMN(), 4)),Dex!$A$2:$C99,3,false),"")} | F2: {=iferror(VLOOKUP(INDIRECT(ADDRESS(ROW()+1,COLUMN(), 4)),Dex!$A$2:$C99,3,false),"")} | G2: {=iferror(VLOOKUP(INDIRECT(ADDRESS(ROW()+1,COLUMN(), 4)),Dex!$A$2:$C99,3,false),"")} | H2: {=iferror(VLOOKUP("TRAINER_PIC_ELITE_FOUR_SIDNEY",Sprites!$A$1:$B99,2,false),"")}
B3: Greninja | C3: Necrozma | D3: Nidoking | E3: Urshifu | F3: Yveltal | G3: Gyarados-Mega
A4: Level | B4: 99 | C4: 99 | D4: 99 | E4: 100 | F4: 100 | G4: 100
A5: Held Item | B5: Focus Sash | C5: Leftovers | D5: Life Orb | E5: Roseli Berry | F5: Dread Plate | G5: Gyaradosite
A6: Ability | B6: Protean | C6: Prism Armor | D6: Sheer Force | E6: Unseen Fist | F6: Dark Aura | G6: Mold Breaker
A7: Nature | B7: Timid | C7: Naive | D7: Timid | E7: Jolly | F7: Timid | G7: Jolly
A8: Moves | B8: Dark Pulse | C8: Photon Geyser | D8: Sludge Wave | E8: Close Combat | F8: Dark Pulse | G8: Waterfall
B9: Scald | C9: Heat Wave | D9: Earth Power | E9: Wicked Blow | F9: Oblivion Wing | G9: Crunch
B10: Spikes | C10: Knock Off | D10: Ice Beam | E10: Sucker Punch | F10: Heat Wave | G10: Earthquake
B11: Toxic Spikes | C11: Stealth Rock | D11: Dark Pulse | E11: Swords Dance | F11: Roost | G11: Dragon Dance
A12: Name | B12: Elite Four Sidney [Double]
A13: Pokémon | B13: {=iferror(VLOOKUP(INDIRECT(ADDRESS(ROW()+1,COLUMN(), 4)),Dex!$A$2:$C99,3,false),"")} | C13: {=iferror(VLOOKUP(INDIRECT(ADDRESS(ROW()+1,COLUMN(), 4)),Dex!$A$2:$C99,3,false),"")} | D13: {=iferror(VLOOKUP(INDIRECT(ADDRESS(ROW()+1,COLUMN(), 4)),Dex!$A$2:$C99,3,false),"")} | E13: {=iferror(VLOOKUP(INDIRECT(ADDRESS(ROW()+1,COLUMN(), 4)),Dex!$A$2:$C99,3,false),"")} | F13: {=iferror(VLOOKUP(INDIRECT(ADDRESS(ROW()+1,COLUMN(), 4)),Dex!$A$2:$C99,3,false),"")} | G13: {=iferror(VLOOKUP(INDIRECT(ADDRESS(ROW()+1,COLUMN(), 4)),Dex!$A$2:$C99,3,false),"")} | H13: {=iferror(VLOOKUP("TRAINER_PIC_ELITE_FOUR_SIDNEY",Sprites!$A$1:$B99,2,false),"")}
B14: Incineroar | C14: Articuno-Galar | D14: Overqwil | E14: Urshifu | F14: Darkrai | G14: Gyarados-Mega
A15: Level | B15: 99 | C15: 99 | D15: 99 | E15: 100 | F15: 100 | G15: 100
A16: Held Item | B16: Iapapa Berry | C16: Lum Berry | D16: Assault Vest | E16: Focus Sash | F16: Life Orb | G16: Gyaradosite
A17: Ability | B17: Intimidate | C17: Competitive | D17: Intimidate | E17: Unseen Fist | F17: Bad Dreams | G17: Mold Breaker
A18: Nature | B18: Jolly | C18: Timid | D18: Jolly | E18: Jolly | F18: Timid | G18: Jolly
A19: Moves | B19: Flare Blitz | C19: Hurricane | D19: Gunk Shot | E19: Close Combat | F19: Dark Pulse | G19: Waterfall
B20: Knock Off | C20: Freezing Glare | D20: Crunch | E20: Wicked Blow | F20: Sludge Bomb | G20: Power Whip
B21: Fire Spin | C21: Hypnosis | D21: Fell Stinger | E21: Reversal | F21: Aura Sphere | G21: Lash Out
B22: Fake Out | C22: Tailwind | D22: Icy Wind | E22: Detect | F22: Dark Void | G22: Icy Wind
A23: Name | B23: Elite Four Phoebe
A24: Pokémon | B24: {=iferror(VLOOKUP(INDIRECT(ADDRESS(ROW()+1,COLUMN(), 4)),Dex!$A$2:$C99,3,false),"")} | C24: {=iferror(VLOOKUP(INDIRECT(ADDRESS(ROW()+1,COLUMN(), 4)),Dex!$A$2:$C99,3,false),"")} | D24: {=iferror(VLOOKUP(INDIRECT(ADDRESS(ROW()+1,COLUMN(), 4)),Dex!$A$2:$C99,3,false),"")} | E24: {=iferror(VLOOKUP(INDIRECT(ADDRESS(ROW()+1,COLUMN(), 4)),Dex!$A$2:$C99,3,false),"")} | F24: {=iferror(VLOOKUP(INDIRECT(ADDRESS(ROW()+1,COLUMN(), 4)),Dex!$A$2:$C99,3,false),"")} | G24: {=iferror(VLOOKUP(INDIRECT(ADDRESS(ROW()+1,COLUMN(), 4)),Dex!$A$2:$C99,3,false),"")} | H24: {=iferror(VLOOKUP("TRAINER_PIC_ELITE_FOUR_PHOEBE",Sprites!$A$1:$B99,2,false),"")}
B25: Crobat | C25: Zoroark-Hisui | D25: Gothitelle | E25: Lunala | F25: Marshadow | G25: Gengar-Mega
A26: Level | B26: 99 | C26: 100 | D26: 99 | E26: 100 | F26: 100 | G26: 100
A27: Held Item | B27: Flying Gem | C27: Life Orb | D27: Assault Vest | E27: Power Herb | F27: Lum Berry | G27: Gengarite
A28: Ability | B28: Inner Focus | C28: Illusion | D28: Shadow Tag | E28: Shadow Shield | F28: Technician | G28: Shadow Tag
A29: Nature | B29: Jolly | C29: Hasty | D29: Timid | E29: Timid | F29: Jolly | G29: Timid
A30: Moves | B30: Acrobatics | C30: Shadow Ball | D30: Psychic | E30: Moongeist Beam | F30: Close Combat | G30: Sludge Wave
B31: Super Fang | C31: Flamethrower | D31: Thunderbolt | E31: Meteor Beam | F31: Shadow Sneak | G31: Shadow Ball
B32: Hypnosis | C32: U-turn | D32: Dazzling Gleam | E32: Moonblast | F32: Knock Off | G32: Focus Blast
B33: Roost | C33: Grass Knot | D33: Shadow Ball | E33: Roost | F33: Bulk Up | G33: Destiny Bond
A34: Name | B34: Elite Four Phoebe [Double]
A35: Pokémon | B35: {=iferror(VLOOKUP(INDIRECT(ADDRESS(ROW()+1,COLUMN(), 4)),Dex!$A$2:$C99,3,false),"")} | C35: {=iferror(VLOOKUP(INDIRECT(ADDRESS(ROW()+1,COLUMN(), 4)),Dex!$A$2:$C99,3,false),"")} | D35: {=iferror(VLOOKUP(INDIRECT(ADDRESS(ROW()+1,COLUMN(), 4)),Dex!$A$2:$C99,3,false),"")} | E35: {=iferror(VLOOKUP(INDIRECT(ADDRESS(ROW()+1,COLUMN(), 4)),Dex!$A$2:$C99,3,false),"")} | F35: {=iferror(VLOOKUP(INDIRECT(ADDRESS(ROW()+1,COLUMN(), 4)),Dex!$A$2:$C99,3,false),"")} | G35: {=iferror(VLOOKUP(INDIRECT(ADDRESS(ROW()+1,COLUMN(), 4)),Dex!$A$2:$C99,3,false),"")} | H35: {=iferror(VLOOKUP("TRAINER_PIC_ELITE_FOUR_PHOEBE",Sprites!$A$1:$B99,2,false),"")}
B36: Decidueye-Hisui | C36: Chandelure | D36: Blastoise | E36: Lunala | F36: Giratina-Origin | G36: Gengar-Mega
A37: Level | B37: 99 | C37: 100 | D37: 99 | E37: 100 | F37: 100 | G37: 100
A38: Held Item | B38: Focus Sash | C38: Kasib Berry | D38: Iapapa Berry | E38: Power Herb | F38: Griseous Orb | G38: Gengarite
A39: Ability | B39: Scrappy | C39: Shadow Tag | D39: Torrent | E39: Shadow Shield | F39: Levitate | G39: Shadow Tag
A40: Nature | B40: Jolly | C40: Timid | D40: Timid | E40: Timid | F40: Naive | G40: Timid
...
